Workbook
Name Slicer_Location: #N/A
Name Slicer_Month: #N/A
Name Slicer_Product_Category: #N/A

Sheet Sheet2
A3: Sum of Purchase Amount | B3: Column Labels
A4: Row Labels | B4: 01-2026 | C4: 02-2025 | D4: 02-2026 | E4: 03-2025 | F4: 04-2025 | G4: 05-2025 | H4: 06-2025 | I4: 07-2025 | J4: 08-2025 | K4: 09-2025 | L4: 10-2025 | M4: 11-2025 | N4: 12-2025 | O4: Grand Total
A5: Beauty | B5: 3431.68 | C5: 383.65 | D5: 1953.33 | E5: 1168.4 | F5: 1987.34 | G5: 3111.1 | H5: 2934.15 | I5: 2015.88 | J5: 3838.54 | K5: 2840.14 | L5: 2778.28 | M5: 4300.9 | N5: 3030.45 | O5: 33773.84
A6: Clothing | B6: 2447.73 | C6: 509.19 | D6: 2079.96 | E6: 4303.47 | F6: 2149.46 | G6: 2497.9 | H6: 3179.13 | I6: 2279.43 | J6: 5068.02 | K6: 2478.16 | L6: 5646.22 | M6: 1799.69 | N6: 3273.57 | O6: 37711.93
A7: Electronics | B7: 3748.18 | C7: 1327.08 | D7: 395.12 | E7: 3165.29 | F7: 3420.26 | G7: 2049.7 | H7: 3859.69 | I7: 3917.65 | J7: 4069.69 | K7: 3710.16 | L7: 4160.97 | M7: 3822.11 | N7: 2187.1 | O7: 39833
A8: Home | B8: 3924.44 | C8: 692.48 | D8: 1849.62 | E8: 2067.31 | F8: 2316.86 | G8: 3089.92 | H8: 3040.11 | I8: 302.52 | J8: 2535.48 | K8: 2580.1 | L8: 2452.24 | M8: 2681.55 | N8: 2618.46 | O8: 30151.09
A9: Sports | B9: 3625.47 | C9: 820.58 | D9: 2034.94 | E9: 2065.33 | F9: 2509.93 | G9: 3212.13 | H9: 2341.94 | I9: 1147.07 | J9: 4607.41 | K9: 2600.4 | L9: 3356.8 | M9: 3142.99 | N9: 3343.09 | O9: 34808.08
A10: Grand Total | B10: 17177.5 | C10: 3732.98 | D10: 8312.97 | E10: 12769.8 | F10: 12383.85 | G10: 13960.75 | H10: 15355.02 | I10: 9662.55 | J10: 20119.14 | K10: 14208.96 | L10: 18394.51 | M10: 15747.24 | N10: 14452.67 | O10: 176277.94

Sheet Sheet3
A3: Location | B3: Revenue
A4: Boston | B4: 22276.02
A5: Chicago | B5: 23195.26
A6: Houston | B6: 26357.77
A7: Los Angeles | B7: 27180.96
A8: Miami | B8: 25269.48
A9: New York | B9: 23768.22
A10: Seattle | B10: 28230.23
A11: Grand Total | B11: 176277.94

Sheet ecommerce_data
A1: Customer ID | B1: Purchase Date | C1: Month | D1: Product Category | E1: Product Name | F1: Purchase Amount | G1: Location | H1: Repeat Customers | I1: Orders Count | J1: Customer Type | K1: Number of Customers | L1: Average Order Value | M1: Repeat Customer %
A2: C167 | B2: 46068 | C2: =TEXT(B:B, "mm-yyyy") -> 02-2026 | D2: Beauty | E2: Perfume | F2: 130.84 | G2: Houston | H2: =IF(I2>1, 1, 0) -> 1 | I2: =COUNTIF($A:$A, A2) -> 3 | J2: =IF(COUNTIF($A$2:A2,A2)=1,"New","Repeat") -> New | K2: =IFERROR(__xludf.DUMMYFUNCTION("IF(I2=""4+"", COUNTUNIQUE(FILTER(A:A, I:I>=4)), COUNTUNIQUE(FILTER(A:A, I:I=I2)) )"),42) -> 42 | L2: =AVERAGE(F:F) -> 251.82563 | M2: =SUM(H:H)/COUNTA(A:A) -> 0.96433666
A3: C147 | B3: 45988 | C3: =TEXT(B:B, "mm-yyyy") -> 11-2025 | D3: Clothing | E3: Jeans | F3: 11.25 | G3: Houston | H3: =IF(I3>1, 1, 0) -> 1 | I3: =COUNTIF($A:$A, A3) -> 2 | J3: =IF(COUNTIF($A$2:A3,A3)=1,"New","Repeat") -> New | K3: =IFERROR(__xludf.DUMMYFUNCTION("IF(I3=""4+"", COUNTUNIQUE(FILTER(A:A, I:I>=4)), COUNTUNIQUE(FILTER(A:A, I:I=I3)) )"),37) -> 37
A4: C195 | B4: 45794 | C4: =TEXT(B:B, "mm-yyyy") -> 05-2025 | D4: Clothing | E4: Shoes | F4: 60.34 | G4: Seattle | H4: =IF(I4>1, 1, 0) -> 1 | I4: =COUNTIF($A:$A, A4) -> 5 | J4: =IF(COUNTIF($A$2:A4,A4)=1,"New","Repeat") -> New | K4: =IFERROR(__xludf.DUMMYFUNCTION("IF(I4=""4+"", COUNTUNIQUE(FILTER(A:A, I:I>=4)), COUNTUNIQUE(FILTER(A:A, I:I=I4)) )"),34) -> 34
A5: C178 | B5: 45745 | C5: =TEXT(B:B, "mm-yyyy") -> 03-2025 | D5: Clothing | E5: Jacket | F5: 455.49 | G5: Los Angeles | H5: =IF(I5>1, 1, 0) -> 0 | I5: =COUNTIF($A:$A, A5) -> 1 | J5: =IF(COUNTIF($A$2:A5,A5)=1,"New","Repeat") -> New | K5: =IFERROR(__xludf.DUMMYFUNCTION("IF(I5=""4+"", COUNTUNIQUE(FILTER(A:A, I:I>=4)), COUNTUNIQUE(FILTER(A:A, I:I=I5)) )"),24) -> 24
A6: C183 | B6: 45939 | C6: =TEXT(B:B, "mm-yyyy") -> 10-2025 | D6: Clothing | E6: Shoes | F6: 199.87 | G6: Los Angeles | H6: =IF(I6>1, 1, 0) -> 1 | I6: =COUNTIF($A:$A, A6) -> 9 | J6: =IF(COUNTIF($A$2:A6,A6)=1,"New","Repeat") -> New | K6: =IFERROR(__xludf.DUMMYFUNCTION("IF(I6=""4+"", COUNTUNIQUE(FILTER(A:A, I:I>=4)), COUNTUNIQUE(FILTER(A:A, I:I=I6)) )"),2) -> 2
A7: C123 | B7: 45932 | C7: =TEXT(B:B, "mm-yyyy") -> 10-2025 | D7: Electronics | E7: Keyboard | F7: 217.11 | G7: New York | H7: =IF(I7>1, 1, 0) -> 1 | I7: =COUNTIF($A:$A, A7) -> 3 | J7: =IF(COUNTIF($A$2:A7,A7)=1,"New","Repeat") -> New | K7: =IFERROR(__xludf.DUMMYFUNCTION("IF(I7=""4+"", COUNTUNIQUE(FILTER(A:A, I:I>=4)), COUNTUNIQUE(FILTER(A:A, I:I=I7)) )"),42) -> 42
A8: C183 | B8: 45956 | C8: =TEXT(B:B, "mm-yyyy") -> 10-2025 | D8: Clothing | E8: Jacket | F8: 49.89 | G8: New York | H8: =IF(I8>1, 1, 0) -> 1 | I8: =COUNTIF($A:$A, A8) -> 9 | J8: =IF(COUNTIF($A$2:A8,A8)=1,"New","Repeat") -> Repeat | K8: =IFERROR(__xludf.DUMMYFUNCTION("IF(I8=""4+"", COUNTUNIQUE(FILTER(A:A, I:I>=4)), COUNTUNIQUE(FILTER(A:A, I:I=I8)) )"),2) -> 2
A9: C033 | B9: 45937 | C9: =TEXT(B:B, "mm-yyyy") -> 10-2025 | D9: Beauty | E9: Shampoo | F9: 225.76 | G9: Chicago | H9: =IF(I9>1, 1, 0) -> 1 | I9: =COUNTIF($A:$A, A9) -> 5 | J9: =IF(COUNTIF($A$2:A9,A9)=1,"New","Repeat") -> New | K9: =IFERROR(__xludf.DUMMYFUNCTION("IF(I9=""4+"", COUNTUNIQUE(FILTER(A:A, I:I>=4)), COUNTUNIQUE(FILTER(A:A, I:I=I9)) )"),34) -> 34
A10: C172 | B10: 45873 | C10: =TEXT(B:B, "mm-yyyy") -> 08-2025 | D10: Sports | E10: Dumbbells | F10: 332.71 | G10: Boston | H10: =IF(I10>1, 1, 0) -> 0 | I10: =COUNTIF($A:$A, A10) -> 1 | J10: =IF(COUNTIF($A$2:A10,A10)=1,"New","Repeat") -> New | K10: =IFERROR(__xludf.DUMMYFUNCTION("IF(I10=""4+"", COUNTUNIQUE(FILTER(A:A, I:I>=4)), COUNTUNIQUE(FILTER(A:A, I:I=I10)) )"),24) -> 24
A11: C060 | B11: 45759 | C11: =TEXT(B:B, "mm-yyyy") -> 04-2025 | D11: Sports | E11: Tennis Racket | F11: 88.7 | G11: Seattle | H11: =IF(I11>1, 1, 0) -> 1 | I11: =COUNTIF($A:$A, A11) -> 3 | J11: =IF(COUNTIF($A$2:A11,A11)=1,"New","Repeat") -> New | K11: =IFERROR(__xludf.DUMMYFUNCTION("IF(I11=""4+"", COUNTUNIQUE(FILTER(A:A, I:I>=4)), COUNTUNIQUE(FILTER(A:A, I:I=I11)) )"),42) -> 42
A12: C107 | B12: 46020 | C12: =TEXT(B:B, "mm-yyyy") -> 12-2025 | D12: Beauty | E12: Foundation | F12: 62.24 | G12: Los Angeles | H12: =IF(I12>1, 1, 0) -> 1 | I12: =COUNTIF($A:$A, A12) -> 5 | J12: =IF(COUNTIF($A$2:A12,A12)=1,"New","Repeat") -> New | K12: =IFERROR(__xludf.DUMMYFUNCTION("IF(I12=""4+"", COUNTUNIQUE(FILTER(A:A, I:I>=4)), COUNTUNIQUE(FILTER(A:A, I:I=I12)) )"),34) -> 34
A13: C008 | B13: 45711 | C13: =TEXT(B:B, "mm-yyyy") -> 02-2025 | D13: Electronics | E13: Smartphone | F13: 493.22 | G13: Houston | H13: =IF(I13>1, 1, 0) -> 1 | I13: =COUNTIF($A:$A, A13) -> 4 | J13: =IF(COUNTIF($A$2:A13,A13)=1,"New","Repeat") -> New | K13: =IFERROR(__xludf.DUMMYFUNCTION("IF(I13=""4+"", COUNTUNIQUE(FILTER(A:A, I:I>=4)), COUNTUNIQUE(FILTER(A:A, I:I=I13)) )"),32) -> 32
A14: C091 | B14: 46068 | C14: =TEXT(B:B, "mm-yyyy") -> 02-2026 | D14: Electronics | E14: Headphones | F14: 104.02 | G14: New York | H14: =IF(I14>1, 1, 0) -> 1 | I14: =COUNTIF($A:$A, A14) -> 5 | J14: =IF(COUNTIF($A$2:A14,A14)=1,"New","Repeat") -> New | K14: =IFERROR(__xludf.DUMMYFUNCTION("IF(I14=""4+"", COUNTUNIQUE(FILTER(A:A, I:I>=4)), COUNTUNIQUE(FILTER(A:A, I:I=I14)) )"),34) -> 34
A15: C070 | B15: 45833 | C15: =TEXT(B:B, "mm-yyyy") -> 06-2025 | D15: Clothing | E15: Sweater | F15: 66.29 | G15: Chicago | H15: =IF(I15>1, 1, 0) -> 1 | I15: =COUNTIF($A:$A, A15) -> 4 | J15: =IF(COUNTIF($A$2:A15,A15)=1,"New","Repeat") -> New | K15: =IFERROR(__xludf.DUMMYFUNCTION("IF(I15=""4+"", COUNTUNIQUE(FILTER(A:A, I:I>=4)), COUNTUNIQUE(FILTER(A:A, I:I=I15)) )"),32) -> 32
A16: C190 | B16: 45873 | C16: =TEXT(B:B, "mm-yyyy") -> 08-2025 | D16: Sports | E16: Dumbbells | F16: 478.65 | G16: Seattle | H16: =IF(I16>1, 1, 0) -> 0 | I16: =COUNTIF($A:$A, A16) -> 1 | J16: =IF(COUNTIF($A$2:A16,A16)=1,"New","Repeat") -> New | K16: =IFERROR(__xludf.DUMMYFUNCTION("IF(I16=""4+"", COUNTUNIQUE(FILTER(A:A, I:I>=4)), COUNTUNIQUE(FILTER(A:A, I:I=I16)) )"),24) -> 24
A17: C067 | B17: 45795 | C17: =TEXT(B:B, "mm-yyyy") -> 05-2025 | D17: Beauty | E17: Foundation | F17: 326.18 | G17: Houston | H17: =IF(I17>1, 1, 0) -> 1 | I17: =COUNTIF($A:$A, A17) -> 4 | J17: =IF(COUNTIF($A$2:A17,A17)=1,"New","Repeat") -> New | K17: =IFERROR(__xludf.DUMMYFUNCTION("IF(I17=""4+"", COUNTUNIQUE(FILTER(A:A, I:I>=4)), COUNTUNIQUE(FILTER(A:A, I:I=I17)) )"),32) -> 32
A18: C075 | B18: 45740 | C18: =TEXT(B:B, "mm-yyyy") -> 03-2025 | D18: Home | E18: Chair | F18: 432.34 | G18: New York | H18: =IF(I18>1, 1, 0) -> 1 | I18: =COUNTIF($A:$A, A18) -> 8 | J18: =IF(COUNTIF($A$2:A18,A18)=1,"New","Repeat") -> New | K18: =IFERROR(__xludf.DUMMYFUNCTION("IF(I18=""4+"", COUNTUNIQUE(FILTER(A:A, I:I>=4)), COUNTUNIQUE(FILTER(A:A, I:I=I18)) )"),1) -> 1
A19: C047 | B19: 45779 | C19: =TEXT(B:B, "mm-yyyy") -> 05-2025 | D19: Sports | E19: Yoga Mat | F19: 108.15 | G19: Chicago | H19: =IF(I19>1, 1, 0) -> 1 | I19: =COUNTIF($A:$A, A19) -> 3 | J19: =IF(COUNTIF($A$2:A19,A19)=1,"New","Repeat") -> New | K19: =IFERROR(__xludf.DUMMYFUNCTION("IF(I19=""4+"", COUNTUNIQUE(FILTER(A:A, I:I>=4)), COUNTUNIQUE(FILTER(A:A, I:I=I19)) )"),42) -> 42
A20: C023 | B20: 45770 | C20: =TEXT(B:B, "mm-yyyy") -> 04-2025 | D20: Electronics | E20: Smartphone | F20: 267.75 | G20: Houston | H20: =IF(I20>1, 1, 0) -> 1 | I20: =COUNTIF($A:$A, A20) -> 5 | J20: =IF(COUNTIF($A$2:A20,A20)=1,"New","Repeat") -> New | K20: =IFERROR(__xludf.DUMMYFUNCTION("IF(I20=""4+"", COUNTUNIQUE(FILTER(A:A, I:I>=4)), COUNTUNIQUE(FILTER(A:A, I:I=I20)) )"),34) -> 34
A21: C001 | B21: 45891 | C21: =TEXT(B:B, "mm-yyyy") -> 08-2025 | D21: Electronics | E21: Keyboard | F21: 117.93 | G21: Houston | H21: =IF(I21>1, 1, 0) -> 1 | I21: =COUNTIF($A:$A, A21) -> 4 | J21: =IF(COUNTIF($A$2:A21,A21)=1,"New","Repeat") -> New | K21: =IFERROR(__xludf.DUMMYFUNCTION("IF(I21=""4+"", COUNTUNIQUE(FILTER(A:A, I:I>=4)), COUNTUNIQUE(FILTER(A:A, I:I=I21)) )"),32) -> 32
A22: C182 | B22: 45740 | C22: =TEXT(B:B, "mm-yyyy") -> 03-2025 | D22: Sports | E22: Soccer Ball | F22: 288.34 | G22: Boston | H22: =IF(I22>1, 1, 0) -> 1 | I22: =COUNTIF($A:$A, A22) -> 3 | J22: =IF(COUNTIF($A$2:A22,A22)=1,"New","Repeat") -> New | K22: =IFERROR(__xludf.DUMMYFUNCTION("IF(I22=""4+"", COUNTUNIQUE(FILTER(A:A, I:I>=4)), COUNTUNIQUE(FILTER(A:A, I:I=I22)) )"),42) -> 42
A23: C075 | B23: 45937 | C23: =TEXT(B:B, "mm-yyyy") -> 10-2025 | D23: Beauty | E23: Lipstick | F23: 146.52 | G23: Los Angeles | H23: =IF(I23>1, 1, 0) -> 1 | I23: =COUNTIF($A:$A, A23) -> 8 | J23: =IF(COUNTIF($A$2:A23,A23)=1,"New","Repeat") -> Repeat | K23: =IFERROR(__xludf.DUMMYFUNCTION("IF(I23=""4+"", COUNTUNIQUE(FILTER(A:A, I:I>=4)), COUNTUNIQUE(FILTER(A:A, I:I=I23)) )"),1) -> 1
A24: C100 | B24: 45789 | C24: =TEXT(B:B, "mm-yyyy") -> 05-2025 | D24: Sports | E24: Soccer Ball | F24: 80.82 | G24: Los Angeles | H24: =IF(I24>1, 1, 0) -> 1 | I24: =COUNTIF($A:$A, A24) -> 2 | J24: =IF(COUNTIF($A$2:A24,A24)=1,"New","Repeat") -> New | K24: =IFERROR(__xludf.DUMMYFUNCTION("IF(I24=""4+"", COUNTUNIQUE(FILTER(A:A, I:I>=4)), COUNTUNIQUE(FILTER(A:A, I:I=I24)) )"),37) -> 37
A25: C025 | B25: 45774 | C25: =TEXT(B:B, "mm-yyyy") -> 04-2025 | D25: Clothing | E25: Shoes | F25: 406.37 | G25: Boston | H25: =IF(I25>1, 1, 0) -> 1 | I25: =COUNTIF($A:$A, A25) -> 6 | J25: =IF(COUNTIF($A$2:A25,A25)=1,"New","Repeat") -> New | K25: =IFERROR(__xludf.DUMMYFUNCTION("IF(I25=""4+"", COUNTUNIQUE(FILTER(A:A, I:I>=4)), COUNTUNIQUE(FILTER(A:A, I:I=I25)) )"),19) -> 19
A26: C040 | B26: 46051 | C26: =TEXT(B:B, "mm-yyyy") -> 01-2026 | D26: Electronics | E26: Keyboard | F26: 410.52 | G26: Houston | H26: =IF(I26>1, 1, 0) -> 1 | I26: =COUNTIF($A:$A, A26) -> 4 | J26: =IF(COUNTIF($A$2:A26,A26)=1,"New","Repeat") -> New | K26: =IFERROR(__xludf.DUMMYFUNCTION("IF(I26=""4+"", COUNTUNIQUE(FILTER(A:A, I:I>=4)), COUNTUNIQUE(FILTER(A:A, I:I=I26)) )"),32) -> 32
A27: C101 | B27: 45959 | C27: =TEXT(B:B, "mm-yyyy") -> 10-2025 | D27: Sports | E27: Soccer Ball | F27: 87.88 | G27: New York | H27: =IF(I27>1, 1, 0) -> 1 | I27: =COUNTIF($A:$A, A27) -> 6 | J27: =IF(COUNTIF($A$2:A27,A27)=1,"New","Repeat") -> New | K27: =IFERROR(__xludf.DUMMYFUNCTION("IF(I27=""4+"", COUNTUNIQUE(FILTER(A:A, I:I>=4)), COUNTUNIQUE(FILTER(A:A, I:I=I27)) )"),19) -> 19
A28: C031 | B28: 46001 | C28: =TEXT(B:B, "mm-yyyy") -> 12-2025 | D28: Clothing | E28: Sweater | F28: 387.1 | G28: Los Angeles | H28: =IF(I28>1, 1, 0) -> 1 | I28: =COUNTIF($A:$A, A28) -> 5 | J28: =IF(COUNTIF($A$2:A28,A28)=1,"New","Repeat") -> New | K28: =IFERROR(__xludf.DUMMYFUNCTION("IF(I28=""4+"", COUNTUNIQUE(FILTER(A:A, I:I>=4)), COUNTUNIQUE(FILTER(A:A, I:I=I28)) )"),34) -> 34
A29: C008 | B29: 45890 | C29: =TEXT(B:B, "mm-yyyy") -> 08-2025 | D29: Clothing | E29: T-shirt | F29: 467.51 | G29: New York | H29: =IF(I29>1, 1, 0) -> 1 | I29: =COUNTIF($A:$A, A29) -> 4 | J29: =IF(COUNTIF($A$2:A29,A29)=1,"New","Repeat") -> Repeat | K29: =IFERROR(__xludf.DUMMYFUNCTION("IF(I29=""4+"", COUNTUNIQUE(FILTER(A:A, I:I>=4)), COUNTUNIQUE(FILTER(A:A, I:I=I29)) )"),32) -> 32
A30: C136 | B30: 45784 | C30: =TEXT(B:B, "mm-yyyy") -> 05-2025 | D30: Beauty | E30: Foundation | F30: 466.89 | G30: Seattle | H30: =IF(I30>1, 1, 0) -> 1 | I30: =COUNTIF($A:$A, A30) -> 3 | J30: =IF(COUNTIF($A$2:A30,A30)=1,"New","Repeat") -> New | K30: =IFERROR(__xludf.DUMMYFUNCTION("IF(I30=""4+"", COUNTUNIQUE(FILTER(A:A, I:I>=4)), COUNTUNIQUE(FILTER(A:A, I:I=I30)) )"),42) -> 42
A31: C194 | B31: 45734 | C31: =TEXT(B:B, "mm-yyyy") -> 03-2025 | D31: Home | E31: Toaster | F31: 351.58 | G31: Houston | H31: =IF(I31>1, 1, 0) -> 1 | I31: =COUNTIF($A:$A, A31) -> 7 | J31: =IF(COUNTIF($A$2:A31,A31)=1,"New","Repeat") -> New | K31: =IFERROR(__xludf.DUMMYFUNCTION("IF(I31=""4+"", COUNTUNIQUE(FILTER(A:A, I:I>=4)), COUNTUNIQUE(FILTER(A:A, I:I=I31)) )"),4) -> 4
A32: C005 | B32: 45910 | C32: =TEXT(B:B, "mm-yyyy") -> 09-2025 | D32: Beauty | E32: Lipstick | F32: 187.71 | G32: Miami | H32: =IF(I32>1, 1, 0) -> 1 | I32: =COUNTIF($A:$A, A32) -> 4 | J32: =IF(COUNTIF($A$2:A32,A32)=1,"New","Repeat") -> New | K32: =IFERROR(__xludf.DUMMYFUNCTION("IF(I32=""4+"", COUNTUNIQUE(FILTER(A:A, I:I>=4)), COUNTUNIQUE(FILTER(A:A, I:I=I32)) )"),32) -> 32
A33: C069 | B33: 45880 | C33: =TEXT(B:B, "mm-yyyy") -> 08-2025 | D33: Home | E33: Lamp | F33: 330.98 | G33: Chicago | H33: =IF(I33>1, 1, 0) -> 1 | I33: =COUNTIF($A:$A, A33) -> 7 | J33: =IF(COUNTIF($A$2:A33,A33)=1,"New","Repeat") -> New | K33: =IFERROR(__xludf.DUMMYFUNCTION("IF(I33=""4+"", COUNTUNIQUE(FILTER(A:A, I:I>=4)), COUNTUNIQUE(FILTER(A:A, I:I=I33)) )"),4) -> 4
A34: C056 | B34: 45718 | C34: =TEXT(B:B, "mm-yyyy") -> 03-2025 | D34: Electronics | E34: Mouse | F34: 345.51 | G34: Seattle | H34: =IF(I34>1, 1, 0) -> 1 | I34: =COUNTIF($A:$A, A34) -> 3 | J34: =IF(COUNTIF($A$2:A34,A34)=1,"New","Repeat") -> New | K34: =IFERROR(__xludf.DUMMYFUNCTION("IF(I34=""4+"", COUNTUNIQUE(FILTER(A:A, I:I>=4)), COUNTUNIQUE(FILTER(A:A, I:I=I34)) )"),42) -> 42
A35: C183 | B35: 45739 | C35: =TEXT(B:B, "mm-yyyy") -> 03-2025 | D35: Electronics | E35: Smartphone | F35: 437.67 | G35: New York | H35: =IF(I35>1, 1, 0) -> 1 | I35: =COUNTIF($A:$A, A35) -> 9 | J35: =IF(COUNTIF($A$2:A35,A35)=1,"New","Repeat") -> Repeat | K35: =IFERROR(__xludf.DUMMYFUNCTION("IF(I35=""4+"", COUNTUNIQUE(FILTER(A:A, I:I>=4)), COUNTUNIQUE(FILTER(A:A, I:I=I35)) )"),2) -> 2
A36: C010 | B36: 45936 | C36: =TEXT(B:B, "mm-yyyy") -> 10-2025 | D36: Clothing | E36: Jacket | F36: 116.58 | G36: Los Angeles | H36: =IF(I36>1, 1, 0) -> 1 | I36: =COUNTIF($A:$A, A36) -> 3 | J36: =IF(COUNTIF($A$2:A36,A36)=1,"New","Repeat") -> New | K36: =IFERROR(__xludf.DUMMYFUNCTION("IF(I36=""4+"", COUNTUNIQUE(FILTER(A:A, I:I>=4)), COUNTUNIQUE(FILTER(A:A, I:I=I36)) )"),42) -> 42
A37: C026 | B37: 45865 | C37: =TEXT(B:B, "mm-yyyy") -> 07-2025 | D37: Sports | E37: Dumbbells | F37: 120.01 | G37: Chicago | H37: =IF(I37>1, 1, 0) -> 1 | I37: =COUNTIF($A:$A, A37) -> 3 | J37: =IF(COUNTIF($A$2:A37,A37)=1,"New","Repeat") -> New | K37: =IFERROR(__xludf.DUMMYFUNCTION("IF(I37=""4+"", COUNTUNIQUE(FILTER(A:A, I:I>=4)), COUNTUNIQUE(FILTER(A:A, I:I=I37)) )"),42) -> 42
A38: C180 | B38: 45910 | C38: =TEXT(B:B, "mm-yyyy") -> 09-2025 | D38: Home | E38: Toaster | F38: 55.22 | G38: Houston | H38: =IF(I38>1, 1, 0) -> 1 | I38: =COUNTIF($A:$A, A38) -> 6 | J38: =IF(COUNTIF($A$2:A38,A38)=1,"New","Repeat") -> New | K38: =IFERROR(__xludf.DUMMYFUNCTION("IF(I38=""4+"", COUNTUNIQUE(FILTER(A:A, I:I>=4)), COUNTUNIQUE(FILTER(A:A, I:I=I38)) )"),19) -> 19
A39: C049 | B39: 46062 | C39: =TEXT(B:B, "mm-yyyy") -> 02-2026 | D39: Home | E39: Chair | F39: 77.56 | G39: Boston | H39: =IF(I39>1, 1, 0) -> 1 | I39: =COUNTIF($A:$A, A39) -> 4 | J39: =IF(COUNTIF($A$2:A39,A39)=1,"New","Repeat") -> New | K39: =IFERROR(__xludf.DUMMYFUNCTION("IF(I39=""4+"", COUNTUNIQUE(FILTER(A:A, I:I>=4)), COUNTUNIQUE(FILTER(A:A, I:I=I39)) )"),32) -> 32
A40: C067 | B40: 45982 | C40: =TEXT(B:B, "mm-yyyy") -> 11-2025 | D40: Electronics | E40: Keyboard | F40: 426.31 | G40: Seattle | H40: =IF(I40>1, 1, 0) -> 1 | I40: =COUNTIF($A:$A, A40) -> 4 | J40: =IF(COUNTIF($A$2:A40,A40)=1,"New","Repeat") -> Repeat | K40: =IFERROR(__xludf.DUMMYFUNCTION("IF(I40=""4+"", COUNTUNIQUE(FILTER(A:A, I:I>=4)), COUNTUNIQUE(FILTER(A:A, I:I=I40)) )"),32) -> 32
...

Sheet Pivot Table 14
A1: Orders Count | B1: COUNTUNIQUE of Customer ID
B2: 0
A3: 1 | B3: 24
A4: 2 | B4: 37
A5: 3 | B5: 42
A6: 4 | B6: 32
A7: 5 | B7: 34
A8: 6 | B8: 19
A9: 7 | B9: 4
A10: 8 | B10: 1
A11: 9 | B11: 2
A12: 10 | B12: 1
A13: Grand Total | B13: 196

Sheet Pivot Table 12
A2: Month | B2: Revenue | C2: Order Count
A3: 01-2026 | B3: 17177.5 | C3: 64
A4: 02-2025 | B4: 3732.98 | C4: 16
A5: 02-2026 | B5: 8312.97 | C5: 39
A6: 03-2025 | B6: 12769.8 | C6: 50
A7: 04-2025 | B7: 12383.85 | C7: 51
A8: 05-2025 | B8: 13960.75 | C8: 57
A9: 06-2025 | B9: 15355.02 | C9: 64
A10: 07-2025 | B10: 9662.55 | C10: 37
A11: 08-2025 | B11: 20119.14 | C11: 77
A12: 09-2025 | B12: 14208.96 | C12: 55
A13: 10-2025 | B13: 18394.51 | C13: 72
A14: 11-2025 | B14: 15747.24 | C14: 60
A15: 12-2025 | B15: 14452.67 | C15: 58
A16: (blank)
A17: Grand Total | B17: 176277.94 | C17: 700

Sheet Pivot Table 11
A1: Sales | B1: Month
A2: Product Category | B2: 01-2026 | C2: 02-2025 | D2: 02-2026 | E2: 03-2025 | F2: 04-2025 | G2: 05-2025 | H2: 06-2025 | I2: 07-2025 | J2: 08-2025 | K2: 09-2025 | L2: 10-2025 | M2: 11-2025 | N2: 12-2025 | O2: (blank) | P2: Grand Total
A3: Beauty | B3: 3431.68 | C3: 383.65 | D3: 1953.33 | E3: 1168.4 | F3: 1987.34 | G3: 3111.1 | H3: 2934.15 | I3: 2015.88 | J3: 3838.54 | K3: 2840.14 | L3: 2778.28 | M3: 4300.9 | N3: 3030.45 | P3: 33773.84
A4: Clothing | B4: 2447.73 | C4: 509.19 | D4: 2079.96 | E4: 4303.47 | F4: 2149.46 | G4: 2497.9 | H4: 3179.13 | I4: 2279.43 | J4: 5068.02 | K4: 2478.16 | L4: 5646.22 | M4: 1799.69 | N4: 3273.57 | P4: 37711.93
A5: Electronics | B5: 3748.18 | C5: 1327.08 | D5: 395.12 | E5: 3165.29 | F5: 3420.26 | G5: 2049.7 | H5: 3859.69 | I5: 3917.65 | J5: 4069.69 | K5: 3710.16 | L5: 4160.97 | M5: 3822.11 | N5: 2187.1 | P5: 39833
A6: Home | B6: 3924.44 | C6: 692.48 | D6: 1849.62 | E6: 2067.31 | F6: 2316.86 | G6: 3089.92 | H6: 3040.11 | I6: 302.52 | J6: 2535.48 | K6: 2580.1 | L6: 2452.24 | M6: 2681.55 | N6: 2618.46 | P6: 30151.09
A7: Sports | B7: 3625.47 | C7: 820.58 | D7: 2034.94 | E7: 2065.33 | F7: 2509.93 | G7: 3212.13 | H7: 2341.94 | I7: 1147.07 | J7: 4607.41 | K7: 2600.4 | L7: 3356.8 | M7: 3142.99 | N7: 3343.09 | P7: 34808.08
A8: (blank)
A9: Grand Total | B9: 17177.5 | C9: 3732.98 | D9: 8312.97 | E9: 12769.8 | F9: 12383.85 | G9: 13960.75 | H9: 15355.02 | I9: 9662.55 | J9: 20119.14 | K9: 14208.96 | L9: 18394.51 | M9: 15747.24 | N9: 14452.67 | P9: 176277.94

Sheet Pivot Table 9
A1: Month | B1: SUM of Purchase Amount
A2: 01-2026 | B2: 17177.5
A3: 02-2025 | B3: 3732.98
A4: 02-2026 | B4: 8312.97
A5: 03-2025 | B5: 12769.8
A6: 04-2025 | B6: 12383.85
A7: 05-2025 | B7: 13960.75
A8: 06-2025 | B8: 15355.02
A9: 07-2025 | B9: 9662.55
A10: 08-2025 | B10: 20119.14
A11: 09-2025 | B11: 14208.96
A12: 10-2025 | B12: 18394.51
A13: 11-2025 | B13: 15747.24
A14: 12-2025 | B14: 14452.67
A15: (blank)
A16: Grand Total | B16: 176277.94

Sheet Total Revenue
A1: Product Category | B1: Total Revenue
A2: Beauty | B2: =SUMIF(ecommerce_data!D:D, A2, ecommerce_data!F:F) -> 33773.84 | D2: Product Category | E2: Total Revenue
A3: Clothing | B3: =SUMIF(ecommerce_data!D:D, A3, ecommerce_data!F:F) -> 37711.93 | D3: Beauty | E3: 33773.84
A4: Electronics | B4: =SUMIF(ecommerce_data!D:D, A4, ecommerce_data!F:F) -> 39833 | D4: Clothing | E4: 37711.93
A5: Sports | B5: =SUMIF(ecommerce_data!D:D, A5, ecommerce_data!F:F) -> 34808.08 | D5: Electronics | E5: 39833
A6: Home | B6: =SUMIF(ecommerce_data!D:D, A6, ecommerce_data!F:F) -> 30151.09 | D6: Home | E6: 30151.09
D7: Sports | E7: 34808.08
D8: Grand Total | E8: 176277.94

Sheet Top_Customers
A1: =IFERROR(__xludf.DUMMYFUNCTION("Query(ecommerce_data!A:F, ""select A, sum(F) where F is not null group by A order by sum(F) desc limit 5"", 1)"),"Customer ID") -> Customer ID | B1: =IFERROR(__xludf.DUMMYFUNCTION("""COMPUTED_VALUE"""),"sum Purchase Amount") -> sum Purchase Amount
A2: =IFERROR(__xludf.DUMMYFUNCTION("""COMPUTED_VALUE"""),"C183") -> C183 | B2: =IFERROR(__xludf.DUMMYFUNCTION("""COMPUTED_VALUE"""),2892.28) -> 2892.28
A3: =IFERROR(__xludf.DUMMYFUNCTION("""COMPUTED_VALUE"""),"C075") -> C075 | B3: =IFERROR(__xludf.DUMMYFUNCTION("""COMPUTED_VALUE"""),2652.27) -> 2652.27
A4: =IFERROR(__xludf.DUMMYFUNCTION("""COMPUTED_VALUE"""),"C199") -> C199 | B4: =IFERROR(__xludf.DUMMYFUNCTION("""COMPUTED_VALUE"""),2515.2) -> 2515.2
A5: =IFERROR(__xludf.DUMMYFUNCTION("""COMPUTED_VALUE"""),"C134") -> C134 | B5: =IFERROR(__xludf.DUMMYFUNCTION("""COMPUTED_VALUE"""),2011.91999999999) -> 2011.92
A6: =IFERROR(__xludf.DUMMYFUNCTION("""COMPUTED_VALUE"""),"C006") -> C006 | B6: =IFERROR(__xludf.DUMMYFUNCTION("""COMPUTED_VALUE"""),1982.29) -> 1982.29
A8: Customer ID | B8: SUM of sum Purchase Amount
A9: C006 | B9: 1982.29
A10: C075 | B10: 2652.27
A11: C134 | B11: 2011.92
A12: C183 | B12: 2892.28
A13: C199 | B13: 2515.2
A14: Grand Total | B14: 12053.96

Sheet Dashboard

Sheet Pivot Table 4
A1: Customer Type | B1: COUNTUNIQUE of Customer ID
B2: 0
A3: New | B3: 196
A4: Repeat | B4: 172
A5: Grand Total | B5: 196

Sheet Pivot Table 2
A1: Location
A2: Boston
A3: Chicago
A4: Houston
A5: Los Angeles
A6: Miami
A7: New York
A8: Seattle
A9: (blank)
A10: Grand Total
